Workbook
Name ALT: модель!$A$123
Name AST: модель!$A$132
Name closed: модель!$C$3
Name E1F: модель!$A$126
Name E2F: модель!$A$127
Name E3F: модель!$A$128
Name MXQ: модель!$A$131
Name NLC: модель!$A$129
Name renegat: модель!$E$3
Name RUNC: эксперимент!$C$2
Name SRVT: модель!$B$9:$D$12
Name start: модель!$A$3

Sheet модель
B1: Табличная модель системы массового обслуживания с 3 серверами и ограничением времени ожидания
A2: Начало | C2: Конец | E2: Уйти если ожидание больше
A3: 0.375 | C3: 0.75 | E3: 4 | F3: мин
A6: вероят ность | B6: нижняя | C6: верхняя | D6: время
B7: граница | C7: граница | D7: сервиса
D8: (мин)
A9: 0.15 | B9: 0 | C9: =B9+A9 -> 0.15 | D9: 3
A10: 0.25 | B10: =C9 -> 0.15 | C10: =B10+A10 -> 0.4 | D10: 7
A11: 0.25 | B11: =C10 -> 0.4 | C11: =B11+A11 -> 0.65 | D11: 9
A12: 0.35 | B12: =C11 -> 0.65 | C12: =B12+A12 -> 1 | D12: 17
B14: время до | D14: время обс- | F14: момент | G14: прогноз | I14: время | J14: прогноз 1 | K14: прогноз 2 | L14: прогноз 3 | M14: факт. | U14: б/о | V14: до обсл. | X14: время | Y14: итог. | Z14: длина
A15: клиент | B15: прихода | C15: интервал | D15: луживания | E15: интервал | F15: времени | G15: времени | H15: отка-- | I15: ухода из | J15: начала обс- | K15: начала обс- | L15: начала обс- | M15: время | N15: номер | O15: оператор 1 факт | Q15: оператор 2 | S15: оператор 3 | U15: время в | V15: время в | W15: длит-ть | X15: обслуж- | Y15: время | Z15: очереди
A16: # | B16: клиента | C16: между | D16: на сервере | E16: обслуж- | F16: прихода | G16: ожидания | H16: зался | I16: очереди | J16: луживания | K16: луживания | L16: луживания | M16: начала | N16: сервера | O16: нач | P16: кон | Q16: нач | R16: кон | S16: нач | T16: кон | U16: очереди | V16: очереди | W16: пребыв | X16: ивания | Y16: ухода | Z16: к началу
B17: (мин) | C17: клиентами | D17: (мин) | E17: ивания | F17: (ч:мин) | G17: (ч:мин) | H17: ждать ? | I17: (ч:мин) | J17: (ч:мин) | K17: (ч:мин) | L17: (ч:мин) | M17: (ч:мин) | O17: (ч:мин) | P17: (ч:мин) | Q17: (ч:мин) | R17: (ч:мин) | S17: (ч:мин) | T17: (ч:мин) | U17: (ч:мин) | V17: (ч:мин) | W17: (ч:мин) | X17: (с отказами)
F19: =start -> 0.375 | P19: =start -> 0.375 | R19: =start -> 0.375 | T19: =start -> 0.375
A20: 1 | B20: =RANDBETWEEN(1,3) -> 1 | C20: =B20/(60*24) -> 0.00069444444 | D20: =VLOOKUP(RAND(),SRVT,3) -> 7 | E20: =D20/1440 -> 0.0048611111 | F20: =IF(ISTEXT(F19),"",IF(F19+ C20>=closed,"закрыто",F19+C20)) -> 0.37569444 | G20: =IF(ISTEXT(F20),"",M20-F20) -> 0 | H20: =IF(G20>(renegat/1440),"ушел","") | I20: =IF(H20="ушел",F20+(renegat/1440),"") | J20: =MAX(P19,$F20) -> 0.37569444 | K20: =MAX(R19,$F20) -> 0.37569444 | L20: =MAX(T19,$F20) -> 0.37569444 | M20: =IF(ISTEXT(F20),"",MIN(J20:L20)) -> 0.37569444 | N20: =IF(OR(ISTEXT(F20),H20="ушел"),"",MATCH(M20,J20:L20,0)) -> 1 | O20: =IF($N20=1,M20,"") -> 0.37569444 | P20: =IF($N20=1,O20+$E20,P19) -> 0.38055556 | Q20: =IF($N20=2,M20,"") | R20: =IF($N20=2,Q20+$E20,R19) -> 0.375 | S20: =IF($N20=3,M20,"") | T20: =IF($N20=3,S20+$E20,T19) -> 0.375 | U20: =IF(H20="ушел",I20-F20,"") | V20: =IF(H20="ушел","",F20+G20) -> 0.37569444 | W20: =Y20-F20 -> 0.0048611111 | X20: =IF(H20="ушел",W20,$E20+G20) -> 0.0048611111 | Y20: =IF(H20="ушел",I20,CHOOSE(N20,P20,R20,T20)) -> 0.38055556 | Z20: 0
A21: =IF(ISTEXT(F21),"закрыто",A20+1) -> 2 | B21: =RANDBETWEEN(1,3) -> 1 | C21: =B21/(60*24) -> 0.00069444444 | D21: =VLOOKUP(RAND(),SRVT,3) -> 17 | E21: =D21/1440 -> 0.011805556 | F21: =IF(ISTEXT(F20),"",IF(F20+ C21>=closed,"закрыто",F20+C21)) -> 0.37638889 | G21: =IF(ISTEXT(F21),"",M21-F21) -> 0 | H21: =IF(G21>(renegat/1440),"ушел","") | I21: =IF(H21="ушел",F21+(renegat/1440),"") | J21: =IF(ISTEXT($F21),"",MAX($P$19:P20,$F21)) -> 0.38055556 | K21: =IF(ISTEXT($F21),"",MAX($R$19:R20,$F21)) -> 0.37638889 | L21: =IF(ISTEXT($F21),"",MAX(T19:T20,$F21)) -> 0.37638889 | M21: =IF(ISTEXT(F21),"",MIN(J21:L21)) -> 0.37638889 | N21: =IF(OR(ISTEXT(F21),H21="ушел"),"",MATCH(M21,J21:L21,0)) -> 2 | O21: =IF($N21=1,M21,"") | P21: =IF($N21=1,O21+$E21,P20) -> 0.38055556 | Q21: =IF($N21=2,M21,"") -> 0.37638889 | R21: =IF($N21=2,Q21+$E21,R20) -> 0.38819444 | S21: =IF($N21=3,M21,"") | T21: =IF($N21=3,S21+$E21,T20) -> 0.375 | U21: =IF(H21="ушел",I21-F21,"") | V21: =IF(H21="ушел","",F21+G21) -> 0.37638889 | W21: =Y21-F21 -> 0.011805556 | X21: =IF(H21="ушел",W21,$E21+G21) -> 0.011805556 | Y21: =IF(H21="ушел",I21,CHOOSE(N21,P21,R21,T21)) -> 0.38819444 | Z21: =COUNTIF($M$19:$M20,">"&$F21) -> 0
A22: =IF(ISTEXT(F22),"закрыто",A21+1) -> 3 | B22: =RANDBETWEEN(1,3) -> 2 | C22: =B22/(60*24) -> 0.0013888889 | D22: =VLOOKUP(RAND(),SRVT,3) -> 9 | E22: =D22/1440 -> 0.00625 | F22: =IF(ISTEXT(F21),"",IF(F21+ C22>=closed,"закрыто",F21+C22)) -> 0.37777778 | G22: =IF(ISTEXT(F22),"",M22-F22) -> 0 | H22: =IF(G22>(renegat/1440),"ушел","") | I22: =IF(H22="ушел",F22+(renegat/1440),"") | J22: =IF(ISTEXT($F22),"",MAX($P$19:P21,$F22)) -> 0.38055556 | K22: =IF(ISTEXT($F22),"",MAX($R$19:R21,$F22)) -> 0.38819444 | L22: =IF(ISTEXT($F22),"",MAX(T20:T21,$F22)) -> 0.37777778 | M22: =IF(ISTEXT(F22),"",MIN(J22:L22)) -> 0.37777778 | N22: =IF(OR(ISTEXT(F22),H22="ушел"),"",MATCH(M22,J22:L22,0)) -> 3 | O22: =IF($N22=1,M22,"") | P22: =IF($N22=1,O22+$E22,P21) -> 0.38055556 | Q22: =IF($N22=2,M22,"") | R22: =IF($N22=2,Q22+$E22,R21) -> 0.38819444 | S22: =IF($N22=3,M22,"") -> 0.37777778 | T22: =IF($N22=3,S22+$E22,T21) -> 0.38402778 | U22: =IF(H22="ушел",I22-F22,"") | V22: =IF(H22="ушел","",F22+G22) -> 0.37777778 | W22: =Y22-F22 -> 0.00625 | X22: =IF(H22="ушел",W22,$E22+G22) -> 0.00625 | Y22: =IF(H22="ушел",I22,CHOOSE(N22,P22,R22,T22)) -> 0.38402778 | Z22: =COUNTIF($M$19:$M21,">"&$F22) -> 0
A23: =IF(ISTEXT(F23),"закрыто",A22+1) -> 4 | B23: =RANDBETWEEN(1,3) -> 3 | C23: =B23/(60*24) -> 0.0020833333 | D23: =VLOOKUP(RAND(),SRVT,3) -> 9 | E23: =D23/1440 -> 0.00625 | F23: =IF(ISTEXT(F22),"",IF(F22+ C23>=closed,"закрыто",F22+C23)) -> 0.37986111 | G23: =IF(ISTEXT(F23),"",M23-F23) -> 0.00069444444 | H23: =IF(G23>(renegat/1440),"ушел","") | I23: =IF(H23="ушел",F23+(renegat/1440),"") | J23: =IF(ISTEXT($F23),"",MAX($P$19:P22,$F23)) -> 0.38055556 | K23: =IF(ISTEXT($F23),"",MAX($R$19:R22,$F23)) -> 0.38819444 | L23: =IF(ISTEXT($F23),"",MAX(T21:T22,$F23)) -> 0.38402778 | M23: =IF(ISTEXT(F23),"",MIN(J23:L23)) -> 0.38055556 | N23: =IF(OR(ISTEXT(F23),H23="ушел"),"",MATCH(M23,J23:L23,0)) -> 1 | O23: =IF($N23=1,M23,"") -> 0.38055556 | P23: =IF($N23=1,O23+$E23,P22) -> 0.38680556 | Q23: =IF($N23=2,M23,"") | R23: =IF($N23=2,Q23+$E23,R22) -> 0.38819444 | S23: =IF($N23=3,M23,"") | T23: =IF($N23=3,S23+$E23,T22) -> 0.38402778 | U23: =IF(H23="ушел",I23-F23,"") | V23: =IF(H23="ушел","",F23+G23) -> 0.38055556 | W23: =Y23-F23 -> 0.0069444444 | X23: =IF(H23="ушел",W23,$E23+G23) -> 0.0069444444 | Y23: =IF(H23="ушел",I23,CHOOSE(N23,P23,R23,T23)) -> 0.38680556 | Z23: =COUNTIF($M$19:$M22,">"&$F23) -> 0
A24: =IF(ISTEXT(F24),"закрыто",A23+1) -> 5 | B24: =RANDBETWEEN(1,3) -> 3 | C24: =B24/(60*24) -> 0.0020833333 | D24: =VLOOKUP(RAND(),SRVT,3) -> 17 | E24: =D24/1440 -> 0.011805556 | F24: =IF(ISTEXT(F23),"",IF(F23+ C24>=closed,"закрыто",F23+C24)) -> 0.38194444 | G24: =IF(ISTEXT(F24),"",M24-F24) -> 0.0020833333 | H24: =IF(G24>(renegat/1440),"ушел","") | I24: =IF(H24="ушел",F24+(renegat/1440),"") | J24: =IF(ISTEXT($F24),"",MAX($P$19:P23,$F24)) -> 0.38680556 | K24: =IF(ISTEXT($F24),"",MAX($R$19:R23,$F24)) -> 0.38819444 | L24: =IF(ISTEXT($F24),"",MAX(T22:T23,$F24)) -> 0.38402778 | M24: =IF(ISTEXT(F24),"",MIN(J24:L24)) -> 0.38402778 | N24: =IF(OR(ISTEXT(F24),H24="ушел"),"",MATCH(M24,J24:L24,0)) -> 3 | O24: =IF($N24=1,M24,"") | P24: =IF($N24=1,O24+$E24,P23) -> 0.38680556 | Q24: =IF($N24=2,M24,"") | R24: =IF($N24=2,Q24+$E24,R23) -> 0.38819444 | S24: =IF($N24=3,M24,"") -> 0.38402778 | T24: =IF($N24=3,S24+$E24,T23) -> 0.39583333 | U24: =IF(H24="ушел",I24-F24,"") | V24: =IF(H24="ушел","",F24+G24) -> 0.38402778 | W24: =Y24-F24 -> 0.013888889 | X24: =IF(H24="ушел",W24,$E24+G24) -> 0.013888889 | Y24: =IF(H24="ушел",I24,CHOOSE(N24,P24,R24,T24)) -> 0.39583333 | Z24: =COUNTIF($M$19:$M23,">"&$F24) -> 0
A25: =IF(ISTEXT(F25),"закрыто",A24+1) -> 6 | B25: =RANDBETWEEN(1,3) -> 1 | C25: =B25/(60*24) -> 0.00069444444 | D25: =VLOOKUP(RAND(),SRVT,3) -> 7 | E25: =D25/1440 -> 0.0048611111 | F25: =IF(ISTEXT(F24),"",IF(F24+ C25>=closed,"закрыто",F24+C25)) -> 0.38263889 | G25: =IF(ISTEXT(F25),"",M25-F25) -> 0.0041666667 | H25: =IF(G25>(renegat/1440),"ушел","") -> ушел | I25: =IF(H25="ушел",F25+(renegat/1440),"") -> 0.38541667 | J25: =IF(ISTEXT($F25),"",MAX($P$19:P24,$F25)) -> 0.38680556 | K25: =IF(ISTEXT($F25),"",MAX($R$19:R24,$F25)) -> 0.38819444 | L25: =IF(ISTEXT($F25),"",MAX(T23:T24,$F25)) -> 0.39583333 | M25: =IF(ISTEXT(F25),"",MIN(J25:L25)) -> 0.38680556 | N25: =IF(OR(ISTEXT(F25),H25="ушел"),"",MATCH(M25,J25:L25,0)) | O25: =IF($N25=1,M25,"") | P25: =IF($N25=1,O25+$E25,P24) -> 0.38680556 | Q25: =IF($N25=2,M25,"") | R25: =IF($N25=2,Q25+$E25,R24) -> 0.38819444 | S25: =IF($N25=3,M25,"") | T25: =IF($N25=3,S25+$E25,T24) -> 0.39583333 | U25: =IF(H25="ушел",I25-F25,"") -> 0.0027777778 | V25: =IF(H25="ушел","",F25+G25) | W25: =Y25-F25 -> 0.0027777778 | X25: =IF(H25="ушел",W25,$E25+G25) -> 0.0027777778 | Y25: =IF(H25="ушел",I25,CHOOSE(N25,P25,R25,T25)) -> 0.38541667 | Z25: =COUNTIF($M$19:$M24,">"&$F25) -> 1
A26: =IF(ISTEXT(F26),"закрыто",A25+1) -> 7 | B26: =RANDBETWEEN(1,3) -> 2 | C26: =B26/(60*24) -> 0.0013888889 | D26: =VLOOKUP(RAND(),SRVT,3) -> 7 | E26: =D26/1440 -> 0.0048611111 | F26: =IF(ISTEXT(F25),"",IF(F25+ C26>=closed,"закрыто",F25+C26)) -> 0.38402778 | G26: =IF(ISTEXT(F26),"",M26-F26) -> 0.0027777778 | H26: =IF(G26>(renegat/1440),"ушел","") | I26: =IF(H26="ушел",F26+(renegat/1440),"") | J26: =IF(ISTEXT($F26),"",MAX($P$19:P25,$F26)) -> 0.38680556 | K26: =IF(ISTEXT($F26),"",MAX($R$19:R25,$F26)) -> 0.38819444 | L26: =IF(ISTEXT($F26),"",MAX(T24:T25,$F26)) -> 0.39583333 | M26: =IF(ISTEXT(F26),"",MIN(J26:L26)) -> 0.38680556 | N26: =IF(OR(ISTEXT(F26),H26="ушел"),"",MATCH(M26,J26:L26,0)) -> 1 | O26: =IF($N26=1,M26,"") -> 0.38680556 | P26: =IF($N26=1,O26+$E26,P25) -> 0.39166667 | Q26: =IF($N26=2,M26,"") | R26: =IF($N26=2,Q26+$E26,R25) -> 0.38819444 | S26: =IF($N26=3,M26,"") | T26: =IF($N26=3,S26+$E26,T25) -> 0.39583333 | U26: =IF(H26="ушел",I26-F26,"") | V26: =IF(H26="ушел","",F26+G26) -> 0.38680556 | W26: =Y26-F26 -> 0.0076388889 | X26: =IF(H26="ушел",W26,$E26+G26) -> 0.0076388889 | Y26: =IF(H26="ушел",I26,CHOOSE(N26,P26,R26,T26)) -> 0.39166667 | Z26: =COUNTIF($M$19:$M25,">"&$F26) -> 1
A27: =IF(ISTEXT(F27),"закрыто",A26+1) -> 8 | B27: =RANDBETWEEN(1,3) -> 2 | C27: =B27/(60*24) -> 0.0013888889 | D27: =VLOOKUP(RAND(),SRVT,3) -> 9 | E27: =D27/1440 -> 0.00625 | F27: =IF(ISTEXT(F26),"",IF(F26+ C27>=closed,"закрыто",F26+C27)) -> 0.38541667 | G27: =IF(ISTEXT(F27),"",M27-F27) -> 0.0027777778 | H27: =IF(G27>(renegat/1440),"ушел","") -> ушел | I27: =IF(H27="ушел",F27+(renegat/1440),"") -> 0.38819444 | J27: =IF(ISTEXT($F27),"",MAX($P$19:P26,$F27)) -> 0.39166667 | K27: =IF(ISTEXT($F27),"",MAX($R$19:R26,$F27)) -> 0.38819444 | L27: =IF(ISTEXT($F27),"",MAX(T25:T26,$F27)) -> 0.39583333 | M27: =IF(ISTEXT(F27),"",MIN(J27:L27)) -> 0.38819444 | N27: =IF(OR(ISTEXT(F27),H27="ушел"),"",MATCH(M27,J27:L27,0)) | O27: =IF($N27=1,M27,"") | P27: =IF($N27=1,O27+$E27,P26) -> 0.39166667 | Q27: =IF($N27=2,M27,"") | R27: =IF($N27=2,Q27+$E27,R26) -> 0.38819444 | S27: =IF($N27=3,M27,"") | T27: =IF($N27=3,S27+$E27,T26) -> 0.39583333 | U27: =IF(H27="ушел",I27-F27,"") -> 0.0027777778 | V27: =IF(H27="ушел","",F27+G27) | W27: =Y27-F27 -> 0.0027777778 | X27: =IF(H27="ушел",W27,$E27+G27) -> 0.0027777778 | Y27: =IF(H27="ушел",I27,CHOOSE(N27,P27,R27,T27)) -> 0.38819444 | Z27: =COUNTIF($M$19:$M26,">"&$F27) -> 2
A28: =IF(ISTEXT(F28),"закрыто",A27+1) -> 9 | B28: =RANDBETWEEN(1,3) -> 3 | C28: =B28/(60*24) -> 0.0020833333 | D28: =VLOOKUP(RAND(),SRVT,3) -> 17 | E28: =D28/1440 -> 0.011805556 | F28: =IF(ISTEXT(F27),"",IF(F27+ C28>=closed,"закрыто",F27+C28)) -> 0.3875 | G28: =IF(ISTEXT(F28),"",M28-F28) -> 0.00069444444 | H28: =IF(G28>(renegat/1440),"ушел","") | I28: =IF(H28="ушел",F28+(renegat/1440),"") | J28: =IF(ISTEXT($F28),"",MAX($P$19:P27,$F28)) -> 0.39166667 | K28: =IF(ISTEXT($F28),"",MAX($R$19:R27,$F28)) -> 0.38819444 | L28: =IF(ISTEXT($F28),"",MAX(T26:T27,$F28)) -> 0.39583333 | M28: =IF(ISTEXT(F28),"",MIN(J28:L28)) -> 0.38819444 | N28: =IF(OR(ISTEXT(F28),H28="ушел"),"",MATCH(M28,J28:L28,0)) -> 2 | O28: =IF($N28=1,M28,"") | P28: =IF($N28=1,O28+$E28,P27) -> 0.39166667 | Q28: =IF($N28=2,M28,"") -> 0.38819444 | R28: =IF($N28=2,Q28+$E28,R27) -> 0.4 | S28: =IF($N28=3,M28,"") | T28: =IF($N28=3,S28+$E28,T27) -> 0.39583333 | U28: =IF(H28="ушел",I28-F28,"") | V28: =IF(H28="ушел","",F28+G28) -> 0.38819444 | W28: =Y28-F28 -> 0.0125 | X28: =IF(H28="ушел",W28,$E28+G28) -> 0.0125 | Y28: =IF(H28="ушел",I28,CHOOSE(N28,P28,R28,T28)) -> 0.4 | Z28: =COUNTIF($M$19:$M27,">"&$F28) -> 1
A29: =IF(ISTEXT(F29),"закрыто",A28+1) -> 10 | B29: =RANDBETWEEN(1,3) -> 2 | C29: =B29/(60*24) -> 0.0013888889 | D29: =VLOOKUP(RAND(),SRVT,3) -> 17 | E29: =D29/1440 -> 0.011805556 | F29: =IF(ISTEXT(F28),"",IF(F28+ C29>=closed,"закрыто",F28+C29)) -> 0.38888889 | G29: =IF(ISTEXT(F29),"",M29-F29) -> 0.0027777778 | H29: =IF(G29>(renegat/1440),"ушел","") | I29: =IF(H29="ушел",F29+(renegat/1440),"") | J29: =IF(ISTEXT($F29),"",MAX($P$19:P28,$F29)) -> 0.39166667 | K29: =IF(ISTEXT($F29),"",MAX($R$19:R28,$F29)) -> 0.4 | L29: =IF(ISTEXT($F29),"",MAX(T27:T28,$F29)) -> 0.39583333 | M29: =IF(ISTEXT(F29),"",MIN(J29:L29)) -> 0.39166667 | N29: =IF(OR(ISTEXT(F29),H29="ушел"),"",MATCH(M29,J29:L29,0)) -> 1 | O29: =IF($N29=1,M29,"") -> 0.39166667 | P29: =IF($N29=1,O29+$E29,P28) -> 0.40347222 | Q29: =IF($N29=2,M29,"") | R29: =IF($N29=2,Q29+$E29,R28) -> 0.4 | S29: =IF($N29=3,M29,"") | T29: =IF($N29=3,S29+$E29,T28) -> 0.39583333 | U29: =IF(H29="ушел",I29-F29,"") | V29: =IF(H29="ушел","",F29+G29) -> 0.39166667 | W29: =Y29-F29 -> 0.014583333 | X29: =IF(H29="ушел",W29,$E29+G29) -> 0.014583333 | Y29: =IF(H29="ушел",I29,CHOOSE(N29,P29,R29,T29)) -> 0.40347222 | Z29: =COUNTIF($M$19:$M28,">"&$F29) -> 0
A30: =IF(ISTEXT(F30),"закрыто",A29+1) -> 11 | B30: =RANDBETWEEN(1,3) -> 2 | C30: =B30/(60*24) -> 0.0013888889 | D30: =VLOOKUP(RAND(),SRVT,3) -> 17 | E30: =D30/1440 -> 0.011805556 | F30: =IF(ISTEXT(F29),"",IF(F29+ C30>=closed,"закрыто",F29+C30)) -> 0.39027778 | G30: =IF(ISTEXT(F30),"",M30-F30) -> 0.0055555556 | H30: =IF(G30>(renegat/1440),"ушел","") -> ушел | I30: =IF(H30="ушел",F30+(renegat/1440),"") -> 0.39305556 | J30: =IF(ISTEXT($F30),"",MAX($P$19:P29,$F30)) -> 0.40347222 | K30: =IF(ISTEXT($F30),"",MAX($R$19:R29,$F30)) -> 0.4 | L30: =IF(ISTEXT($F30),"",MAX(T28:T29,$F30)) -> 0.39583333 | M30: =IF(ISTEXT(F30),"",MIN(J30:L30)) -> 0.39583333 | N30: =IF(OR(ISTEXT(F30),H30="ушел"),"",MATCH(M30,J30:L30,0)) | O30: =IF($N30=1,M30,"") | P30: =IF($N30=1,O30+$E30,P29) -> 0.40347222 | Q30: =IF($N30=2,M30,"") | R30: =IF($N30=2,Q30+$E30,R29) -> 0.4 | S30: =IF($N30=3,M30,"") | T30: =IF($N30=3,S30+$E30,T29) -> 0.39583333 | U30: =IF(H30="ушел",I30-F30,"") -> 0.0027777778 | V30: =IF(H30="ушел","",F30+G30) | W30: =Y30-F30 -> 0.0027777778 | X30: =IF(H30="ушел",W30,$E30+G30) -> 0.0027777778 | Y30: =IF(H30="ушел",I30,CHOOSE(N30,P30,R30,T30)) -> 0.39305556 | Z30: =COUNTIF($M$19:$M29,">"&$F30) -> 1
A31: =IF(ISTEXT(F31),"закрыто",A30+1) -> 12 | B31: =RANDBETWEEN(1,3) -> 1 | C31: =B31/(60*24) -> 0.00069444444 | D31: =VLOOKUP(RAND(),SRVT,3) -> 17 | E31: =D31/1440 -> 0.011805556 | F31: =IF(ISTEXT(F30),"",IF(F30+ C31>=closed,"закрыто",F30+C31)) -> 0.39097222 | G31: =IF(ISTEXT(F31),"",M31-F31) -> 0.0048611111 | H31: =IF(G31>(renegat/1440),"ушел","") -> ушел | I31: =IF(H31="ушел",F31+(renegat/1440),"") -> 0.39375 | J31: =IF(ISTEXT($F31),"",MAX($P$19:P30,$F31)) -> 0.40347222 | K31: =IF(ISTEXT($F31),"",MAX($R$19:R30,$F31)) -> 0.4 | L31: =IF(ISTEXT($F31),"",MAX(T29:T30,$F31)) -> 0.39583333 | M31: =IF(ISTEXT(F31),"",MIN(J31:L31)) -> 0.39583333 | N31: =IF(OR(ISTEXT(F31),H31="ушел"),"",MATCH(M31,J31:L31,0)) | O31: =IF($N31=1,M31,"") | P31: =IF($N31=1,O31+$E31,P30) -> 0.40347222 | Q31: =IF($N31=2,M31,"") | R31: =IF($N31=2,Q31+$E31,R30) -> 0.4 | S31: =IF($N31=3,M31,"") | T31: =IF($N31=3,S31+$E31,T30) -> 0.39583333 | U31: =IF(H31="ушел",I31-F31,"") -> 0.0027777778 | V31: =IF(H31="ушел","",F31+G31) | W31: =Y31-F31 -> 0.0027777778 | X31: =IF(H31="ушел",W31,$E31+G31) -> 0.0027777778 | Y31: =IF(H31="ушел",I31,CHOOSE(N31,P31,R31,T31)) -> 0.39375 | Z31: =COUNTIF($M$19:$M30,">"&$F31) -> 2
A32: =IF(ISTEXT(F32),"закрыто",A31+1) -> 13 | B32: =RANDBETWEEN(1,3) -> 3 | C32: =B32/(60*24) -> 0.0020833333 | D32: =VLOOKUP(RAND(),SRVT,3) -> 7 | E32: =D32/1440 -> 0.0048611111 | F32: =IF(ISTEXT(F31),"",IF(F31+ C32>=closed,"закрыто",F31+C32)) -> 0.39305556 | G32: =IF(ISTEXT(F32),"",M32-F32) -> 0.0027777778 | H32: =IF(G32>(renegat/1440),"ушел","") -> ушел | I32: =IF(H32="ушел",F32+(renegat/1440),"") -> 0.39583333 | J32: =IF(ISTEXT($F32),"",MAX($P$19:P31,$F32)) -> 0.40347222 | K32: =IF(ISTEXT($F32),"",MAX($R$19:R31,$F32)) -> 0.4 | L32: =IF(ISTEXT($F32),"",MAX(T30:T31,$F32)) -> 0.39583333 | M32: =IF(ISTEXT(F32),"",MIN(J32:L32)) -> 0.39583333 | N32: =IF(OR(ISTEXT(F32),H32="ушел"),"",MATCH(M32,J32:L32,0)) | O32: =IF($N32=1,M32,"") | P32: =IF($N32=1,O32+$E32,P31) -> 0.40347222 | Q32: =IF($N32=2,M32,"") | R32: =IF($N32=2,Q32+$E32,R31) -> 0.4 | S32: =IF($N32=3,M32,"") | T32: =IF($N32=3,S32+$E32,T31) -> 0.39583333 | U32: =IF(H32="ушел",I32-F32,"") -> 0.0027777778 | V32: =IF(H32="ушел","",F32+G32) | W32: =Y32-F32 -> 0.0027777778 | X32: =IF(H32="ушел",W32,$E32+G32) -> 0.0027777778 | Y32: =IF(H32="ушел",I32,CHOOSE(N32,P32,R32,T32)) -> 0.39583333 | Z32: =COUNTIF($M$19:$M31,">"&$F32) -> 2
... A119: =IF(ISTEXT(F119),"закрыто",A118+1) -> 100 | B119: =RANDBETWEEN(1,3) -> 2 | C119: =B119/(60*24) -> 0.0013888889 | D119: =VLOOKUP(RAND(),SRVT,3) -> 7 | E119: =D119/1440 -> 0.0048611111 | F119: =IF(ISTEXT(F118),"",IF(F118+ C119>=closed,"закрыто",F118+C119)) -> 0.52013889 | G119: =IF(ISTEXT(F119),"",M119-F119) -> 0.0013888889 | H119: =IF(G119>(renegat/1440),"ушел","") | I119: =IF(H119="ушел",F119+(renegat/1440),"") | J119: =IF(ISTEXT($F119),"",MAX($P$19:P118,$F119)) -> 0.52430556 | K119: =IF(ISTEXT($F119),"",MAX($R$19:R118,$F119)) -> 0.52152778 | L119: =IF(ISTEXT($F119),"",MAX(T117:T118,$F119)) -> 0.52361111 | M119: =IF(ISTEXT(F119),"",MIN(J119:L119)) -> 0.52152778 | N119: =IF(OR(ISTEXT(F119),H119="ушел"),"",MATCH(M119,J119:L119,0)) -> 2 | O119: =IF($N119=1,M119,"") | P119: =IF($N119=1,O119+$E119,P118) -> 0.52430556 | Q119: =IF($N119=2,M119,"") -> 0.52152778 | R119: =IF($N119=2,Q119+$E119,R118) -> 0.52638889 | S119: =IF($N119=3,M119,"") | T119: =IF($N119=3,S119+$E119,T118) -> 0.52361111 | U119: =IF(H119="ушел",I119-F119,"") | V119: =IF(H119="ушел","",F119+G119) -> 0.52152778 | W119: =Y119-F119 -> 0.00625 | X119: =IF(H119="ушел",W119,$E119+G119) -> 0.00625 | Y119: =IF(H119="ушел",I119,CHOOSE(N119,P119,R119,T119)) -> 0.52638889 | Z119: =COUNTIF($M$19:$M118,">"&$F119) -> 0
A123: =AVERAGEIF(H20:H119,"",W20:W119) -> 0.0084813297 | B123: Среднее значение пребывания в системе | O123: =(closed-start)*1440 -> 540 | P123: Общее время работы системы
A124: =AVERAGE(G20:G119) -> 0.0023472222 | B124: Среднее время в очереди на обслуживание | N124: занят | O124: простой
A125: Коэффициенты полезной загрузки для 3 серверов | M125: 1 | N125: =A126 -> 0.3962963 | O125: =1-N125 -> 0.6037037
A126: =( (SUMIF(O20:O119,">0",P20:P119) - SUMIF(O20:O119,">0",O20:O119) ) *1440 ) / $O$123 -> 0.3962963 | B126: коэффициент полезной загрузки для сервера 1 | M126: 2 | N126: =A127 -> 0.4 | O126: =1-N126 -> 0.6
A127: =( (SUMIF(Q20:Q119,">0",R20:R119) - SUMIF(Q20:Q119,">0",Q20:Q119) ) *1440 ) /$O$123 -> 0.4 | B127: коэффициент полезной загрузки для сервера 2 | M127: 3 | N127: =A128 -> 0.38703704 | O127: =1-N127 -> 0.61296296
A128: =( (SUMIF(S20:S119,">0",T20:T119) - SUMIF(S20:S119,">0",S20:S119) ) *1440 ) / $O$123 -> 0.38703704 | B128: коэффициент полезной загрузки для сервера 3
A129: =COUNTIF(H20:H119,"ушел") -> 39 | B129: количество потерянных клиентов
A130: =A129 / A119 -> 0.39 | B130: доля потерянных клиентов
A131: =MAX(Z20:Z119) -> 5 | B131: максимальный размер очереди
A132: =AVERAGE(E20:E119) -> 0.0073055556 | B132: сред.время обслуживания

Sheet эксперимент
B1: Эксперимент1 по модели с 3 серверами и 1 очередью(100) | L1: =MIN(K2:K21) -> 0.0070810565 | M1: =L1 -> 0.0070810565 | N1: {=FREQUENCY(K2:K21, M1:M7)} -> 1 | O1: Данные для частотной гистограммы для характеристики "Среднее время пребывания"
B2: счетчик прогонов: | C2: 0 | K2: 0.0081790123 | L2: =MAX(K2:K21) -> 0.0088577098 | M2: =M1+$L$3 -> 0.0073348641 | N2: 1
A3: № экспе-римента | B3: среднее время пребывания в системе | C3: среднее время обслуживания | D3: количество потерянных заявок на обслуживание | E3: коэффи-циент полезной загрузки сервера 1 | F3: коэффи-циент полезной загрузки сервера 2 | G3: коэффи-циент полезной загрузки сервера 3 | H3: макс. размер очереди | I3: длитель-ность обслужи-вания клиентов | K3: 0.0088577098 | L3: =(L2-L1)/7 -> 0.00025380761 | M3: =M2+$L$3 -> 0.0075886717 | N3: 5
A4: 1 | B4: =IF(RUNC=A4, ALT,B4) -> 0.009247076 | C4: =IF(RUNC=A4,AST,C4) -> 0.007875 | D4: =IF(RUNC=A4,NLC,D4) -> 43 | E4: =IF(RUNC=A4,E1F,E4) -> 0.40185185 | F4: =IF(RUNC=A4,E2F,F4) -> 0.41481481 | G4: =IF(RUNC=A4,E3F,G4) -> 0.41111111 | H4: =IF(RUNC=A4,MXQ,H4) -> 6 | I4: =IF(RUNC=A4,MAX(модель!$O$119:$T$119)-[0]!start,I4) -> 0.16180556 | K4: 0.007739899 | M4: =M3+$L$3 -> 0.0078424793 | N4: 7
A5: 2 | B5: =IF(RUNC=A5, ALT,B5) -> 0.0084889847 | C5: =IF(RUNC=A5,AST,C5) -> 0.0072361111 | D5: =IF(RUNC=A5,NLC,D5) -> 42 | E5: =IF(RUNC=A5,E1F,E5) -> 0.38518519 | F5: =IF(RUNC=A5,E2F,F5) -> 0.38148148 | G5: =IF(RUNC=A5,E3F,G5) -> 0.37407407 | H5: =IF(RUNC=A5,MXQ,H5) -> 5 | I5: =IF(RUNC=A5,MAX(модель!$O$119:$T$119)-[0]!start,I5) -> 0.14861111 | K5: 0.0077172939 | M5: =M4+$L$3 -> 0.0080962869 | N5: 2
A6: 3 | B6: =IF(RUNC=A6, ALT,B6) -> 0.0079637097 | C6: =IF(RUNC=A6,AST,C6) -> 0.0069444444 | D6: =IF(RUNC=A6,NLC,D6) -> 38 | E6: =IF(RUNC=A6,E1F,E6) -> 0.38518519 | F6: =IF(RUNC=A6,E2F,F6) -> 0.37592593 | G6: =IF(RUNC=A6,E3F,G6) -> 0.35 | H6: =IF(RUNC=A6,MXQ,H6) -> 5 | I6: =IF(RUNC=A6,MAX(модель!$O$119:$T$119)-[0]!start,I6) -> 0.14791667 | K6: 0.0075268817 | M6: =M5+$L$3 -> 0.0083500945 | N6: 1
A7: 4 | B7: =IF(RUNC=A7, ALT,B7) -> 0.0082773297 | C7: =IF(RUNC=A7,AST,C7) -> 0.0072638889 | D7: =IF(RUNC=A7,NLC,D7) -> 38 | E7: =IF(RUNC=A7,E1F,E7) -> 0.37777778 | F7: =IF(RUNC=A7,E2F,F7) -> 0.37407407 | G7: =IF(RUNC=A7,E3F,G7) -> 0.39259259 | H7: =IF(RUNC=A7,MXQ,H7) -> 4 | I7: =IF(RUNC=A7,MAX(модель!$O$119:$T$119)-[0]!start,I7) -> 0.15416667 | K7: 0.0076760913 | M7: =M6+$L$3 -> 0.0086039021 | N7: 2
A8: 5 | B8: =IF(RUNC=A8, ALT,B8) -> 0.0077868852 | C8: =IF(RUNC=A8,AST,C8) -> 0.0071388889 | D8: =IF(RUNC=A8,NLC,D8) -> 39 | E8: =IF(RUNC=A8,E1F,E8) -> 0.35925926 | F8: =IF(RUNC=A8,E2F,F8) -> 0.34814815 | G8: =IF(RUNC=A8,E3F,G8) -> 0.35740741 | H8: =IF(RUNC=A8,MXQ,H8) -> 5 | I8: =IF(RUNC=A8,MAX(модель!$O$119:$T$119)-[0]!start,I8) -> 0.14027778 | K8: 0.007358871 | N8: 1
A9: 6 | B9: =IF(RUNC=A9, ALT,B9) -> 0.0085813492 | C9: =IF(RUNC=A9,AST,C9) -> 0.0074722222 | D9: =IF(RUNC=A9,NLC,D9) -> 44 | E9: =IF(RUNC=A9,E1F,E9) -> 0.37222222 | F9: =IF(RUNC=A9,E2F,F9) -> 0.36111111 | G9: =IF(RUNC=A9,E3F,G9) -> 0.35185185 | H9: =IF(RUNC=A9,MXQ,H9) -> 6 | I9: =IF(RUNC=A9,MAX(модель!$O$119:$T$119)-[0]!start,I9) -> 0.14166667 | K9: 0.0075564972
A10: 7 | B10: =IF(RUNC=A10, ALT,B10) -> 0.0089248971 | C10: =IF(RUNC=A10,AST,C10) -> 0.0070972222 | D10: =IF(RUNC=A10,NLC,D10) -> 46 | E10: =IF(RUNC=A10,E1F,E10) -> 0.38148148 | F10: =IF(RUNC=A10,E2F,F10) -> 0.37962963 | G10: =IF(RUNC=A10,E3F,G10) -> 0.36111111 | H10: =IF(RUNC=A10,MXQ,H10) -> 7 | I10: =IF(RUNC=A10,MAX(модель!$O$119:$T$119)-[0]!start,I10) -> 0.14583333 | K10: 0.0076666667
A11: 8 | B11: =IF(RUNC=A11, ALT,B11) -> 0.0093434343 | C11: =IF(RUNC=A11,AST,C11) -> 0.0077361111 | D11: =IF(RUNC=A11,NLC,D11) -> 45 | E11: =IF(RUNC=A11,E1F,E11) -> 0.40925926 | F11: =IF(RUNC=A11,E2F,F11) -> 0.37407407 | G11: =IF(RUNC=A11,E3F,G11) -> 0.4 | H11: =IF(RUNC=A11,MXQ,H11) -> 5 | I11: =IF(RUNC=A11,MAX(модель!$O$119:$T$119)-[0]!start,I11) -> 0.15625 | K11: 0.0085069444
A12: 9 | B12: =IF(RUNC=A12, ALT,B12) -> 0.0083459596 | C12: =IF(RUNC=A12,AST,C12) -> 0.0076111111 | D12: =IF(RUNC=A12,NLC,D12) -> 45 | E12: =IF(RUNC=A12,E1F,E12) -> 0.35 | F12: =IF(RUNC=A12,E2F,F12) -> 0.35185185 | G12: =IF(RUNC=A12,E3F,G12) -> 0.34814815 | H12: =IF(RUNC=A12,MXQ,H12) -> 5 | I12: =IF(RUNC=A12,MAX(модель!$O$119:$T$119)-[0]!start,I12) -> 0.13680556 | K12: 0.007450565
A13: 10 | B13: =IF(RUNC=A13, ALT,B13) -> 0.0080757168 | C13: =IF(RUNC=A13,AST,C13) -> 0.0070416667 | D13: =IF(RUNC=A13,NLC,D13) -> 38 | E13: =IF(RUNC=A13,E1F,E13) -> 0.38703704 | F13: =IF(RUNC=A13,E2F,F13) -> 0.37407407 | G13: =IF(RUNC=A13,E3F,G13) -> 0.38703704 | H13: =IF(RUNC=A13,MXQ,H13) -> 6 | I13: =IF(RUNC=A13,MAX(модель!$O$119:$T$119)-[0]!start,I13) -> 0.15138889 | K13: 0.0070810565
A14: 11 | B14: =IF(RUNC=A14, ALT,B14) -> 0.0083101852 | C14: =IF(RUNC=A14,AST,C14) -> 0.0068472222 | D14: =IF(RUNC=A14,NLC,D14) -> 40 | E14: =IF(RUNC=A14,E1F,E14) -> 0.37407407 | F14: =IF(RUNC=A14,E2F,F14) -> 0.38888889 | G14: =IF(RUNC=A14,E3F,G14) -> 0.37777778 | H14: =IF(RUNC=A14,MXQ,H14) -> 4 | I14: =IF(RUNC=A14,MAX(модель!$O$119:$T$119)-[0]!start,I14) -> 0.15277778 | K14: 0.0077628968
A15: 12 | B15: =IF(RUNC=A15, ALT,B15) -> 0.0091692387 | C15: =IF(RUNC=A15,AST,C15) -> 0.0077361111 | D15: =IF(RUNC=A15,NLC,D15) -> 46 | E15: =IF(RUNC=A15,E1F,E15) -> 0.38333333 | F15: =IF(RUNC=A15,E2F,F15) -> 0.37037037 | G15: =IF(RUNC=A15,E3F,G15) -> 0.36851852 | H15: =IF(RUNC=A15,MXQ,H15) -> 6 | I15: =IF(RUNC=A15,MAX(модель!$O$119:$T$119)-[0]!start,I15) -> 0.14722222 | K15: 0.0079545455
A16: 13 | B16: =IF(RUNC=A16, ALT,B16) -> 0.0078072391 | C16: =IF(RUNC=A16,AST,C16) -> 0.0070416667 | D16: =IF(RUNC=A16,NLC,D16) -> 34 | E16: =IF(RUNC=A16,E1F,E16) -> 0.39259259 | F16: =IF(RUNC=A16,E2F,F16) -> 0.38888889 | G16: =IF(RUNC=A16,E3F,G16) -> 0.3962963 | H16: =IF(RUNC=A16,MXQ,H16) -> 4 | I16: =IF(RUNC=A16,MAX(модель!$O$119:$T$119)-[0]!start,I16) -> 0.15555556 | K16: 0.0077363548
A17: 14 | B17: =IF(RUNC=A17, ALT,B17) -> 0.0085891813 | C17: =IF(RUNC=A17,AST,C17) -> 0.0076111111 | D17: =IF(RUNC=A17,NLC,D17) -> 43 | E17: =IF(RUNC=A17,E1F,E17) -> 0.38333333 | F17: =IF(RUNC=A17,E2F,F17) -> 0.36481481 | G17: =IF(RUNC=A17,E3F,G17) -> 0.3537037 | H17: =IF(RUNC=A17,MXQ,H17) -> 8 | I17: =IF(RUNC=A17,MAX(модель!$O$119:$T$119)-[0]!start,I17) -> 0.14652778 | K17: 0.0076149425
A18: 15 | B18: =IF(RUNC=A18, ALT,B18) -> 0.0084510358 | C18: =IF(RUNC=A18,AST,C18) -> 0.00725 | D18: =IF(RUNC=A18,NLC,D18) -> 41 | E18: =IF(RUNC=A18,E1F,E18) -> 0.3962963 | F18: =IF(RUNC=A18,E2F,F18) -> 0.36481481 | G18: =IF(RUNC=A18,E3F,G18) -> 0.36666667 | H18: =IF(RUNC=A18,MXQ,H18) -> 6 | I18: =IF(RUNC=A18,MAX(модель!$O$119:$T$119)-[0]!start,I18) -> 0.14930556 | K18: 0.0075488683
A19: 16 | B19: =IF(RUNC=A19, ALT,B19) -> 0.0086520947 | C19: =IF(RUNC=A19,AST,C19) -> 0.0077222222 | D19: =IF(RUNC=A19,NLC,D19) -> 39 | E19: =IF(RUNC=A19,E1F,E19) -> 0.40185185 | F19: =IF(RUNC=A19,E2F,F19) -> 0.39444444 | G19: =IF(RUNC=A19,E3F,G19) -> 0.39074074 | H19: =IF(RUNC=A19,MXQ,H19) -> 4 | I19: =IF(RUNC=A19,MAX(модель!$O$119:$T$119)-[0]!start,I19) -> 0.15138889 | K19: 0.0072916667
A20: 17 | B20: =IF(RUNC=A20, ALT,B20) -> 0.0087626263 | C20: =IF(RUNC=A20,AST,C20) -> 0.0071805556 | D20: =IF(RUNC=A20,NLC,D20) -> 45 | E20: =IF(RUNC=A20,E1F,E20) -> 0.37777778 | F20: =IF(RUNC=A20,E2F,F20) -> 0.37777778 | G20: =IF(RUNC=A20,E3F,G20) -> 0.3537037 | H20: =IF(RUNC=A20,MXQ,H20) -> 8 | I20: =IF(RUNC=A20,MAX(модель!$O$119:$T$119)-[0]!start,I20) -> 0.14722222 | K20: 0.0084608844
A21: 18 | B21: =IF(RUNC=A21, ALT,B21) -> 0.0096805556 | C21: =IF(RUNC=A21,AST,C21) -> 0.0082777778 | D21: =IF(RUNC=A21,NLC,D21) -> 50 | E21: =IF(RUNC=A21,E1F,E21) -> 0.36666667 | F21: =IF(RUNC=A21,E2F,F21) -> 0.36111111 | G21: =IF(RUNC=A21,E3F,G21) -> 0.37962963 | H21: =IF(RUNC=A21,MXQ,H21) -> 5 | I21: =IF(RUNC=A21,MAX(модель!$O$119:$T$119)-[0]!start,I21) -> 0.14791667 | K21: 0.007955653
A22: 19 | B22: =IF(RUNC=A22, ALT,B22) -> 0.0080942623 | C22: =IF(RUNC=A22,AST,C22) -> 0.0066527778 | D22: =IF(RUNC=A22,NLC,D22) -> 39 | E22: =IF(RUNC=A22,E1F,E22) -> 0.37962963 | F22: =IF(RUNC=A22,E2F,F22) -> 0.37037037 | G22: =IF(RUNC=A22,E3F,G22) -> 0.36296296 | H22: =IF(RUNC=A22,MXQ,H22) -> 6 | I22: =IF(RUNC=A22,MAX(модель!$O$119:$T$119)-[0]!start,I22) -> 0.14513889
A23: 20 | B23: =IF(RUNC=A23, ALT,B23) -> 0.0085967433 | C23: =IF(RUNC=A23,AST,C23) -> 0.0075 | D23: =IF(RUNC=A23,NLC,D23) -> 42 | E23: =IF(RUNC=A23,E1F,E23) -> 0.37592593 | F23: =IF(RUNC=A23,E2F,F23) -> 0.39814815 | G23: =IF(RUNC=A23,E3F,G23) -> 0.36296296 | H23: =IF(RUNC=A23,MXQ,H23) -> 6 | I23: =IF(RUNC=A23,MAX(модель!$O$119:$T$119)-[0]!start,I23) -> 0.15416667
A25: renegat 2
A27: № экспе-римента | B27: среднее время пребывания в системе | C27: среднее время обслуживания | D27: количество потерянных заявок на обслуживание | E27: коэффи-циент полезной загрузки сервера 1 | F27: коэффи-циент полезной загрузки сервера 2 | G27: коэффи-циент полезной загрузки сервера 3 | H27: макс. размер очереди | I27: длитель-ность обслужи-вания клиентов
A28: 1 | B28: 0.0081790123 | C28: 0.0077083333 | D28: 46 | E28: 0.37222222 | F28: 0.38888889 | G28: 0.35740741 | H28: 4 | I28: 0.15208333 | L28: среднее время пребывания в системе | O28: Среднее время обслуживания | R28: кол-во потерянных клиентов
A29: 2 | B29: 0.0088577098 | C29: 0.0079027778 | D29: 51 | E29: 0.37407407 | F29: 0.35740741 | G29: 0.37407407 | H29: 4 | I29: 0.14791667
A30: 3 | B30: 0.007739899 | C30: 0.0074583333 | D30: 45 | E30: 0.38148148 | F30: 0.3537037 | G30: 0.35925926 | H30: 5 | I30: 0.14930556 | L30: Среднее | M30: 0.007782165 | O30: Среднее | P30: 0.0073131944 | R30: Среднее | S30: 43.75
A31: 4 | B31: 0.0077172939 | C31: 0.0073472222 | D31: 38 | E31: 0.3962963 | F31: 0.40555556 | G31: 0.40185185 | H31: 5 | I31: 0.16319444 | L31: Стандартная ошибка | M31: 9.7506857e-05 | O31: Стандартная ошибка | P31: 7.169224e-05 | R31: Стандартная ошибка | S31: 1.0256577
A32: 5 | B32: 0.0075268817 | C32: 0.0073472222 | D32: 38 | E32: 0.39259259 | F32: 0.41111111 | G32: 0.38148148 | H32: 4 | I32: 0.1625 | L32: Медиана | M32: 0.0076966926 | O32: Медиана | P32: 0.0072916667 | R32: Медиана | S32: 43.5
A33: 6 | B33: 0.0076760913 | C33: 0.00725 | D33: 44 | E33: 0.38333333 | F33: 0.34444444 | G33: 0.36851852 | H33: 6 | I33: 0.14861111 | L33: Мода | M33: #N/A | O33: Мода | P33: 0.0073472222 | R33: Мода | S33: 38
A34: 7 | B34: 0.007358871 | C34: 0.0066666667 | D34: 38 | E34: 0.38518519 | F34: 0.39074074 | G34: 0.36851852 | H34: 5 | I34: 0.15763889 | L34: Стандартное отклонение | M34: 0.00043606392 | O34: Стандартное отклонение | P34: 0.00032061744 | R34: Стандартное отклонение | S34: 4.5868806
A35: 8 | B35: 0.0075564972 | C35: 0.00725 | D35: 41 | E35: 0.36851852 | F35: 0.38518519 | G35: 0.36296296 | H35: 3 | I35: 0.15138889 | L35: Дисперсия выборки | M35: 1.9015174e-07 | O35: Дисперсия выборки | P35: 1.0279554e-07 | R35: Дисперсия выборки | S35: 21.039474
A36: 9 | B36: 0.0076666667 | C36: 0.0074027778 | D36: 50 | E36: 0.32962963 | F36: 0.32962963 | G36: 0.32962963 | H36: 7 | I36: 0.12916667 | L36: Эксцесс | M36: 0.87122805 | O36: Эксцесс | P36: 0.3107464 | R36: Эксцесс | S36: -0.80634392
A37: 10 | B37: 0.0085069444 | C37: 0.0078611111 | D37: 52 | E37: 0.3462963 | F37: 0.35 | G37: 0.34444444 | H37: 6 | I37: 0.1375 | L37: Асимметричность | M37: 0.97805086 | O37: Асимметричность | P37: -0.0808082 | R37: Асимметричность | S37: 0.41152981
A38: 11 | B38: 0.007450565 | C38: 0.0071944444 | D38: 41 | E38: 0.36296296 | F38: 0.37962963 | G38: 0.36296296 | H38: 3 | I38: 0.15 | L38: Интервал | M38: 0.0017766533 | O38: Интервал | P38: 0.0012361111 | R38: Интервал | S38: 14
A39: 12 | B39: 0.0070810565 | C39: 0.0069305556 | D39: 39 | E39: 0.36851852 | F39: 0.35925926 | G39: 0.35555556 | H39: 3 | I39: 0.14513889 | L39: Минимум | M39: 0.0070810565 | O39: Минимум | P39: 0.0066666667 | R39: Минимум | S39: 38
A40: 13 | B40: 0.0077628968 | C40: 0.0073333333 | D40: 44 | E40: 0.38148148 | F40: 0.37962963 | G40: 0.35 | H40: 4 | I40: 0.14930556 | L40: Максимум | M40: 0.0088577098 | O40: Максимум | P40: 0.0079027778 | R40: Максимум | S40: 52
A41: 14 | B41: 0.0079545455 | C41: 0.0076805556 | D41: 45 | E41: 0.37777778 | F41: 0.35740741 | G41: 0.37407407 | H41: 7 | I41: 0.15069444 | L41: Сумма | M41: 0.1556433 | O41: Сумма | P41: 0.14626389 | R41: Сумма | S41: 875
A42: 15 | B42: 0.0077363548 | C42: 0.0071111111 | D42: 43 | E42: 0.38703704 | F42: 0.37222222 | G42: 0.36111111 | H42: 5 | I42: 0.15208333 | L42: Счет | M42: 20 | O42: Счет | P42: 20 | R42: Счет | S42: 20
...
